Workbook

Sheet Document Control
A1: Prepared by | E1: Tool title | I1: Date filled | M1: Quality Target | O1: 4 | Q1: Related Tool
A2: Role | E2: Project Reg. ID | I2: Time Started | M2: Bus. Target | O2: Qlty Delivery | Q2: Prev. Sheet Ref
A3: Checked by | E3: Phase Name | I3: Time cmpltd | M3: Bus. Const | O3: Cost and Risk | Q3: Next Sheet Ref | U3: IMHO GEN
A4: Org/Dept. | C4: R&D and ED | E4: Activity Name | I4: Duration | M4: Iteration Num. | O4: 0 | Q4: Rev Reason | U4: IMHOGEN LTD
A5: Signature | C5: D.E.B | E5: Docu. ID | I5: Date Checked | Q5: Change Dscrpt. | U5: Copyright IMHO GEN 2026.
E6: Sheet Version | I6: Date Approved | U6: All Rights Reserved
A7: Project Request ID
A8: DOCUMENT CONTROL
A9: Find link to source files
A10: DocID | C10: Document Title | M10: Link | Q10: Description
A11: D1.1 | C11: Client Email / Web Form | M11: ➡️ | Q11: The form filled by a new client on the company's website
A12: D.1.2 | C12: Initial Inquiry Notification | M12: ➡️ | Q12: The notification received and a pdf file through emails
A13: D1.3 | C13: Received Request Record | M13: ➡️ | Q13: Recorded details of the project details
A14: D.1.4 | C14: Acknowledgment Email | M14: ➡️ | Q14: Send standard acknowledgment email to the client stating.
A15: D.1.5 | C15: Meeting Time Proposal | M15: ➡️ | Q15: Pre-analysis records and proposed meeting times
A16: D1.6 | C16: Calendar Invite & Agenda | M16: ➡️ | Q16: Link to calender invite and meeting agenda
A17: D.1.7 | C17: Raw Meeting Notes | M17: ➡️ | Q17: Standard template for meeting notes
A18: D.1.8 | C18: Needs Assessment Notes | M18: ➡️ | Q18: Needs assessments records
A19: T3.D1.8a | C19: 3D Modeling Execution (Reverse Engineering) | M19: ➡️ | Q19: his is the "Field Sheet." It ensures that before a machine leaves your sight (or you leave the client's site), all physical dimensions and metadata are captured accurately.
A20: D1.9 | C20: Internal Review Request | M20: ➡️ | Q20: Internal memo for requesting a review of the assessment made
A21: D.1.10 | C21: Capability Assessment | M21: ➡️ | Q21: Reports on capability Assessment
... A29: T3.D1.3a | C29: Technical Intake (If CAD Request Form is selected, use T3-Series bypass sheets) | M29: ➡️ | Q29: This sheet acts as a "3D/Drafting specific" extension of the standard D1.3 Received Request Record.
A30: T3.D2.2a | C30: Drafting Contract Mapping | M30: ➡️
A39: Confidential Notice | M39: Client Name/Organization
M40: Description of Primary activities of Organizaiton

Sheet D1.1 Web Forms
A1: Prepared by | E1: Tool title | G1: Web Forms | I1: Date filled | M1: Quality Target | O1: 4 | Q1: Related Tool
A2: Role | E2: Project Reg. ID | I2: Time Started | M2: Bus. Target | O2: Qlty Delivery | Q2: Prev. Sheet Ref | S2: Doc Control
A3: Checked by | E3: Phase Name | I3: Time cmpltd | M3: Bus. Const | O3: Cost and Risk | Q3: Next Sheet Ref | S3: D1.2 | U3: IMHO GEN
A4: Org/Dept. | C4: R&D and BI | E4: Activity Name | G4: Web Form | I4: Duration | M4: Iteration Num. | O4: 0 | Q4: Rev Reason | U4: IMHOGEN LTD
A5: Signature | C5: D.E.B | E5: Docu. ID | G5: D1.1 | I5: Date Checked | Q5: Change Dscrpt. | U5: Copyright IMHO GEN 2026.
E6: Sheet Version | I6: Date Approved | U6: All Rights Reserved
A7: PROJECT REQUEST ID
A8: D1.1 Web Form Reference
A9: 1.0 CLIENT SUBMISSION REFERENCE
A10: SN | B10: FORM TYPE | H10: DATE SUBMITTED | K10: CLIENT/ORG NAME | O10: DIRECT LINK | S10: STATUS | U10: NOTES
A11: 1 | B11: Product Development Form
A12: 2 | B12: CAD Request Form | H12: 46117 | K12: Syntropy Engineering Solutions | S12: Received | U12: Acknwoledgement email is being sent to client.
A13: 3 | B13: Process Development Form
A14: 4 | B14: Engineering Support/Consultancy
A15: 5 | B15: Others
A17: 2.0 SUPPLEMENTARY UPLOADS (If applicable)
A18: SN | B18: DOCUMENT TYPE | H18: DATE UPLOADED | K18: PROVIDED BY | O18: DIRECT LINK TO FILE | S18: STATUS | U18: NOTES
A35: Confidential Notice | M35: Client Name/Organization
M36: Description of Primary activities of Organizaiton

Sheet D1.2 Initial Inquiry No
A1: Prepared by | C1: C.Fiannaa | E1: Tool title | G1: Initial Inquiry Notification | I1: Date filled | K1: 46117 | M1: Quality Target | O1: 4 | Q1: Related Tool
A2: Role | C2: Ops. Lead | E2: Project Reg. ID | I2: Time Started | K2: 0.58333333 | M2: Bus. Target | O2: Qlty Delivery | Q2: Prev. Sheet Ref | S2: D1.1
A3: Checked by | E3: Phase Name | G3: Onboarding | I3: Time cmpltd | K3: 0.60763889 | M3: Bus. Const | O3: Cost and Risk | Q3: Next Sheet Ref | S3: D1.3 | U3: IMHO GEN
A4: Org/Dept. | C4: R&D and BI | E4: Activity Name | G4: Inquiry Receipt | I4: Duration | M4: Iteration Num. | O4: 0 | Q4: Rev Reason | U4: IMHOGEN LTD
A5: Signature | E5: Docu. ID | G5: D1.2 | I5: Date Checked | Q5: Change Dscrpt. | U5: Copyright IMHO GEN 2026.
E6: Sheet Version | G6: v1.0 | I6: Date Approved | U6: All Rights Reserved
A7: PROJECT REQUEST ID: CAD-1775340276795
A8: D1.2 INTITAL INQUIRY NOTIFICATION
A9: 1.0 NOTIFICATION METADATA
A10: Notification Source (e.g. Web/Direct): | G10: Web (CAD Request Submission Form) | Q10: Date Received | S10: 46117
A11: Sender Email Address: | G11: dir@syntropyengineeringsolutionss.com | Q11: Time Received | S11: 0.60694444
A12: Recipient (IMHOGEN) Address: | G12: IMHO GEN Official CAD Intake Channel (imhogen22@gmail.com) | Q12: Subject Line | S12: CAD Request from Syntropy Engineering Solutions
A14: DIGITAL RECORDS REFERENCE
A15: SN | B15: DOCUMENT TYPE | I15: FILE NAME/DESCRIPTION | Q15: DIRECT LINK TO FILE | U15: STATUS
A16: 1 | B16: Patent Reference | I16: Patent sample drawing.jpeg | Q16: Pantent sample drawing.jpeg | U16: Received
A17: 2 | B17: Prototype image | I17: Prototype image 1.jpeg | Q17: prototype image 1.jpeg | U17: Received
A18: 3 | B18: Prototype image | I18: Prototype image 2.jpeg | Q18: Prototype Image 2.jpeg | U18: Received
A19: 4 | B19: Prototype image | I19: Prototype image 3.jpeg | Q19: Prototype image 3.jpeg | U19: Received
A20: 5 | B20: Prototype image | I20: Prototype image 4.jpeg | Q20: prototype image 4.jpeg | U20: Received
A21: 6 | B21: Submission Record | I21: CAD Request Form Data | Q21: Gmail - Fwd: New CAD Request from Syntropy Engineering Solutions | U21: Logged
A24: 3.0 PRELIMINARY TRIAGE (Spam / Relevance Filter - PID 1.1.2)
A25: SN | B25: Checklist Item | I25: Status (Pass/Fail) | M25: Reviewer Notes
A26: 1 | B26: Is the notification readable and free of malicious links? | I26: PASS | M26: Structured submission via official form. No suspicious links detected.
A27: 2 | B27: Does the request broadly align with IMHOGEN's services? | I27: PASS | M27: Strong alignment with CAD modeling, engineering documentation, and product development.
A28: 3 | B28: Is the contact information apparently valid and legible? | I28: PASS | M28: Email contains spelling irregularities (“egineerinsolutionss”), but phone number and organization context appear valid. Requires verification. But correct email is obtained.
A31: TRIAGE DECISION: | I31: [PROCEED TO D1.3 (Technical Intake) / REJECT AS SPAM]
A35: Confidential Notice | M35: Client Name/Organization | R35: Syntropy Engineering Solutions
A36: Email anomaly detected: Recommend contact verification before contract stage Client located in Suame Magazine: strategic cluster relevance Request involves IP/patent documentation: Signaling High-value + Sensitive Work Attachments provided: Sufficient for initial intake progression | M36: Description of Primary activities of Organizaiton | R36: General engineering fabrication, machining services, and product innovation focused on prototype development within the Suame Magazine industrial cluster.

Sheet D1.3 Received Request Record
A1: Prepared by | E1: Tool title | G1: Received Request Record | I1: Date filled | M1: Quality Target | O1: 4 | Q1: Related Tool | S1: Doc Control
A2: Role | E2: Project Reg. ID | I2: Time Started | M2: Bus. Target | O2: Qlty Delivery | Q2: Prev. Sheet Ref | S2: D1.2
A3: Checked by | E3: Phase Name | G3: Onboarding | I3: Time cmpltd | M3: Bus. Const | O3: Cost and Risk | Q3: Next Sheet Ref | S3: D1.4 | U3: IMHO GEN
A4: Org/Dept. | C4: R&D and BI | E4: Activity Name | G4: Received Request Record | I4: Duration | M4: Iteration Num. | O4: 0 | Q4: Rev Reason | U4: IMHOGEN LTD
A5: Signature | E5: Docu. ID | G5: D1.3 | I5: Date Checked | Q5: Change Dscrpt. | U5: Copyright IMHO GEN 2026.
E6: Sheet Version | G6: v1.0 | I6: Date Approved | U6: All Rights Reserved
A7: PROJECT REQUEST ID: CAD-1775340276795
A8: D1.3 RECEIVED REQUEST RECORD (Universal Translation)
A9: 1.0 CLIENT & PROJECT METADATA
A10: Request Source Form: | G10: https://utfs.io/f/dhn4pYX1fjPsgIdTpoiN7TkPLH5ItxNhDSQYb8uafUiO2CoW | Q10: Client Name: | S10: Frederick Opoku
A11: Project/Product Name: | G11: CAD-1775340276795 | Q11: Company Name: | S11: Syntropy Engineering Solutions
A12: Target Budget (if stated): | G12: None | Q12: Contact Info:
A13: Target Timeline: | G13: 5 worrking days | Q13: Physical Address: | S13: Suame Magazine
A15: 2.0 CORE OBJECTIVES & SCOPE (Client's Stated Vision)
B16: Primary Purpose / Business Goal: | I16: To develop accurate engineering documentation of an existing prototype for Intellectual Property (IP) / Patent Registration, ensuring compliance with patent office illustration standards.
B19: Main Deliverables Requested: | I19: 3D CAD Model of the prototype Patent-compliant technical drawings (line illustrations) Technical drawing package (dimensions & views) Rendered images for visualization Multi-format outputs (SVG, AI, EPS, PDF, STEP)
B22: Specific Constraints Noted: | I22: All outputs must strictly match the prototype (no design changes) Visual style must replicate patent office sample drawing provided No additional features or redesign required Limited source data (images only, no dimensions provided) No periodic drafts requested (internal risk consideration)
A27: 3.0 SYSTEMS ENGINEERING TRANSLATION (Fill N/A if not applicable to request type)
A28: SN | B28: INPUT OPERANDS | M28: OUTPUT OPERANDS
A29: M | B29: Existing physical prototype (mechanical assembly) Prototype images (multiple views) | M29: Digitized 3D CAD model Structured geometric representation of the product
A31: E | B31: N/A
A33: I | B33: Patent sample drawing (format reference) Client instructions and constraints Visual interpretation from images | M33: Engineering drawings (ISO + patent format) Dimensional data and annotations Documentation for IP submission
A35: L | B35: N/A
A37: 3.3 OPERATORS (The System Environment)
A38: Human System: | D38: [Who interacts with it?] | M38: Information System: | P38: [Software/Data integration?]
A39: Technical System: | D39: [Required machinery/tools?] | M39: Management System: | P39: [Maintenance/Lifespan goals?]
A40: Active Environment: | D40: [Indoor/Outdoor/Constraints?]
A41: SN | B41: Technical Notes | Q41: Assignee | U41: Status
B42: This is a Reverse Engineering + IP Documentation Project
B43: Requires measurement validation before modeling finalization
B44: No draft policy from client → internally override with validation checkpoint
B45: High strategic value due to Suame Magazine ecosystem alignment

Sheet T3.D1.3a Technical Intake
A1: Prepared by | C1: C.Fiannaa | E1: Tool title | G1: T3 Technical Intake (Drafting) | I1: Date filled | K1: 46117 | M1: Quality Target | O1: 4 | Q1: Related Tool | S1: T3.D2.2
A2: Role | C2: Ops. Lead | E2: Project Reg. ID | G2: CAD-1775340276795 | I2: Time Started | M2: Bus. Target | O2: Input Accuracy | Q2: Prev. Sheet Ref | S2: D1.1
A3: Org/Dept. | C3: R&D and ED | E3: Activity Name | G3: Technical Intake | I3: Duration | M3: Iteration Num. | O3: 0 | Q3: Rev Reason | S3: IMHOGEN LTD | U3: IMHO GEN
A4: Signature | E4: Docu. ID | G4: T3.D1.3a | I4: Date Checked | Q4: Change Dscrpt. | S4: Tier 3 Fast-Track | U4: IMHOGEN LTD
U5: Copyright IMHO GEN 2026.
U6: All Rights Reserved
A7: PROJECT REQUEST ID: CAD-1775340276795
A8: T3.D1.3a Technical Intake
A9: 1.0 SOURCE ASSET EVALUATION (The Input)
A10: SN | B10: Asset Type | F10: Format/Description | K10: Condition | P10: Action Required | U10: Notes
A11: 1.1 | B11: Existing 3D Model | F11: Not Provided | K11: N/A | P11: Model from Scratch | U11: No baseline CAD data available. Full reconstruction required.
A12: 1.2 | B12: Physical Part | F12: Prototype Provided (images only) | K12: Working Prototype | P12: Site Visit for Measurement | U12: Critical to obtain accurate dimensions. Image-based estimation alone is insufficient for patent-level documentation.
A13: 1.3 | B13: 2D Legacy PDF | F13: Patent Office Sample Drawing (Image Format) | K13: Reference Standard Only | P13: Interpret & Replicate Format | U13: Must strictly follow patent illustration conventions (line weights, views, no shading).
A14: 1.4 | B14: Reference Images | F14: Multiple Prototype Images (JPEG) | K14: Moderate Clarity | P14: Reverse Engineering | U14: Images will guide geometry but not dimensions. Risk of distortion.
A15: 1.5 | B15: Technical Specs | F15: General instruction from client | K15: Limited Detail | P15: Define Assumptions + Validate | U15: Missing explicit dimensions and tolerances. Requires clarification or controlled assumptions.
A17: 2.0 DRAFTING SPECIFICATIONS (The Output)
A18: SN | B18: Requirement | F18: Standard (ISO/ASME) | K18: Tolerance Class | P18: File Format | U18: Notes
A19: 2.1 | B19: Manufacturing Dwgs | F19: ISO 128 | K19: Medium (m) | P19: PDF & DXF | U19: Ensure clarity for fabrication if required in future.
A20: 2.2 | B20: Assembly Dwgs | F20: ISO 128 | K20: N/A | P20: PDF | U20: Exploded views may be required depending on complexity.
A21: 2.3 | B21: 3D Model Output | F21: N/A | K21: N/A | P21: STEP / PDF/PNG | U21: Parametric model required for future edits and reuse.
A22: 2.4 | B22: Paternt Drawings | F22: Patent Office Standard (Black & White Line Art) + Colored Pictorial Representation on Realistic Background. | K22: High Precision (Visual Accuracy) | P22: SVG, AI, EPS, PDF | U22: Must strictly match patent formatting style (no shading, consistent line hierarchy).
A23: 2.5 | B23: Rendered Images | F23: Internal Visualization Standard | K23: N/A | P23: PNG/JPEG | U23: For presentation purposes only (not for patent submission).
A25: 3.0 QUALITY GATE: DATA SUFFICIENCY
A26: Does the provided source data allow for the requested tolerances? (Yes/No): | J26: NO | K26: No explicit dimensions or physical measurements provided. Image-based reconstruction alone cannot guarantee manufacturing or patent-level accuracy.
A27: Is a site visit required for manual measurements? (Yes/No): | J27: YES | K27: To: Capture precise dimensions Validate geometry Ensure patent compliance accuracy Reduce legal/IP risk

Sheet D1.4 Acknowledgement Email
A1: Prepared by | E1: Tool title | G1: Acknowledgement Email | I1: Date filled | M1: Quality Target | O1: 4 | Q1: Related Tool | S1: Doc Control
A2: Role | E2: Project Reg. ID | I2: Time Started | M2: Bus. Target | O2: Qlty Delivery | Q2: Prev. Sheet Ref | S2: D1.3
A3: Checked by | E3: Phase Name | G3: Onboarding | I3: Time cmpltd | M3: Bus. Const | O3: Cost and Risk | Q3: Next Sheet Ref | S3: D1.5 | U3: IMHO GEN
A4: Org/Dept. | C4: R&D and BI | E4: Activity Name | G4: Acknowledgement Email | I4: Duration | M4: Iteration Num. | O4: 0 | Q4: Rev Reason | U4: IMHOGEN LTD
A5: Signature | E5: Docu. ID | G5: D1.4 | I5: Date Checked | Q5: Change Dscrpt. | U5: Copyright IMHO GEN 2026.
E6: Sheet Version | G6: v1.0 | I6: Date Approved | U6: All Rights Reserved
A7: PROJECT REQUEST ID: [Enter ID]
A8: D1.4 ACKNOWLEDGMENT EMAIL RECORD
A9: 1.0 DISPATCH METADATA
A10: Sent To (Client Email): | Q10: Date Sent:
A11: CC / BCC: | Q11: Time Sent:
A12: Subject Line:
A13: Sent By (IMHOGEN Rep):
A15: 2.0 STANDARD EMAIL TEMPLATE (Copy & Paste)
A16: Dear Frederick,
A18: Thank you for reaching out to IMHOGEN LTD. We have successfully received your project inquiry regarding Plastic Extruding Innovation for Patent Application and associated reference sample and Prototype images, submitted on Saturday, 4th April, 2026.
A20: Your request has been assigned the tracking reference : CAD-1775340276795
A22: Our Engineering and R&D team is currently reviewing the initial details you provided. A Project Onboarding Manager will contact you within the next 24-48 hours to propose a time for a brief Technical Discovery Meeting. This meeting will help us better understand your specific constraints to ensure we deliver tailored engineering solution.
A24: If you have any supplementary documents information on scope, please share them.
A25: We look forward to collaborating with you.
A27: (P.S: Request Filled On your behalf by Technical Support Team, find the filled form attached)
A29: Best regards,
A36: 3.0 CRM / DIGITAL RECORD REFERENCE
A37: Link to sent Email | D37: [Who interacts with it?]
A38: Delivery Status | D38: Delivered
A39: Active Environment: | D39: [Indoor/Outdoor/Constraints?]
A40: Note /Replies

Sheet D1.5 Meeting Time Proposal
A1: Prepared by | E1: Tool title | G1: Meeting Time Proposal | I1: Date filled | M1: Quality Target | O1: 4 | Q1: Related Tool | S1: Doc Control
A2: Role | E2: Project Reg. ID | I2: Time Started | M2: Bus. Target | O2: Qlty Delivery | Q2: Prev. Sheet Ref | S2: D1.4
A3: Checked by | E3: Phase Name | G3: Onboarding | I3: Time cmpltd | M3: Bus. Const | O3: Cost and Risk | Q3: Next Sheet Ref | S3: D1.6 | U3: IMHO GEN
A4: Org/Dept. | C4: R&D and BI | E4: Activity Name | G4: Meeting Time Proposal | I4: Duration | M4: Iteration Num. | O4: 0 | Q4: Rev Reason | U4: IMHOGEN LTD
A5: Signature | E5: Docu. ID | G5: D1.5 | I5: Date Checked | Q5: Change Dscrpt. | U5: Copyright IMHO GEN 2026.
E6: Sheet Version | G6: v1.0 | I6: Date Approved | U6: All Rights Reserved
A7: PROJECT REQUEST ID: [Enter ID]
A8: D1.5 MEETING TIME PROPOSAL
A9: 1.0 PRE-MEETING CONTEXT (Internal Tracker)
A10: SLOT No. | F10: Date (DD/MM/YYY) | K10: TIme(Zone) | P10: Status (Pending/Accepted/Declined) | U10: Client Moments
A30: 3.0 STANDARD SCHEDULING EMAIL SCRIPT
A31: Dear [Client Name],
A32: Following our initial review of your request for [Project Name]
A33: This 30-45 minute session will allow our engineering team to understand your operational constraints and exact technical needs.
A34: Please let us know which of the following times works best for you:
A35: - Option 1: [Insert Option 1 Date & Time]
A36: - Option 2: [Insert Option 2 Date & Time]
A37: - Option 3: [Insert Option 3 Date & Time]
A38: If none of these suit your schedule
A39: We look forward to speaking with you.
A40: Best regards,
A41: 4.0 FINAL MEETING CONFIRMATION
A42: Agreed Date: | M42: Agreed Time:
A43: Meeting Platform/Location: | M43: Direct Meeting Link:
A44: Calendar Invite Sent?: | M44: Client Confirmed?:
A45: Note

Sheet D1.6 Calendar Invite & Agenda
A1: Prepared by | E1: Tool title | G1: Calendar Invite & Agenda | I1: Date filled | M1: Quality Target | O1: 4 | Q1: Related Tool | S1: Doc Control
A2: Role | E2: Project Reg. ID | I2: Time Started | M2: Bus. Target | O2: Qlty Delivery | Q2: Prev. Sheet Ref | S2: D1.5
A3: Checked by | E3: Phase Name | G3: Onboarding | I3: Time cmpltd | M3: Bus. Const | O3: Cost and Risk | Q3: Next Sheet Ref | S3: D1.7 | U3: IMHO GEN
A4: Org/Dept. | C4: R&D and BI | E4: Activity Name | G4: Calendar Invite & Agenda | I4: Duration | M4: Iteration Num. | O4: 0 | Q4: Rev Reason | U4: IMHOGEN LTD
A5: Signature | E5: Docu. ID | G5: D1.6 | I5: Date Checked | Q5: Change Dscrpt. | U5: Copyright IMHO GEN 2026.
E6: Sheet Version | G6: v1.0 | I6: Date Approved | U6: All Rights Reserved
A7: PROJECT REQUEST ID: [Enter ID]
A8: D1.6 CALENDAR INVITE & AGENDA
A9: 1.0 FINALIZED MEETING DETAILS
A10: Meeting Date: | F10: Date (DD/MM/YYY) | K10: Meeting Time (Zone)
A11: Platform/Location | K11: Meeting ID/PINI:
A12: IMHOGEN Attendees | K12: Client Attendees:
A15: 2.0 CALENDAR INTEGRATION
A16: SN | B16: Time Allotted | D16: Agenda Topic | K16: Lead Speaker | P16: Meeting Objective / Focus
A17: 1 | B17: 05 Mins | D17: Introductions & Project Overview | K17: Project Manager | P17: Establish rapport and align on the high-level project vision.
A18: 2 | B18: 15 Mins | D18: Technical Requirements (Inputs/Outputs) | K18: Lead Engineer | P18: Extract specific missing data identified in D1.3 (Section 4).
A19: 3 | B19: 10 Mins | D19: Operational Environment & Constraints | K19: Lead Engineer | P19: Define the physical environment and human operator limits.
A20: 4 | B20: 05 Mins | D20: Commercial Expectations (Timeline/Budget) | K20: Project Manager | P20: Ensure IMHOGEN and the client are aligned on business realities.
A21: 5 | B21: 05 Mins | D21: Next Steps & Q&A | K21: Project Manager | P21: Outline the Feasibility Report and Project Briefing stages.
A30: 4.0 PRE-MEETING CHECKLIST
A31: Task | O31: Assignee | T31: Status
A32: Has the Lead Engineer reviewed D1.3 (Received Request Record)? | O32: Lead Engineer
A33: Is the meeting recording software/consent prepared? | O33: Project Manager
A34: Have previous reference documents (D1.1) been opened for screen sharing? | O34: Project Manager
A41: NOTES

Sheet D1.7 Raw Meeting Notes
A1: Prepared by | E1: Tool title | G1: Raw Meeting Notes | I1: Date filled | M1: Quality Target | O1: 4 | Q1: Related Tool | S1: Doc Control
A2: Role | E2: Project Reg. ID | I2: Time Started | M2: Bus. Target | O2: Qlty Delivery | Q2: Prev. Sheet Ref | S2: D1.6
A3: Checked by | E3: Phase Name | G3: Onboarding | I3: Time cmpltd | M3: Bus. Const | O3: Cost and Risk | Q3: Next Sheet Ref | S3: D1.8 | U3: IMHO GEN
A4: Org/Dept. | C4: R&D and BI | E4: Activity Name | G4: Raw Meeting Notes | I4: Duration | M4: Iteration Num. | O4: 0 | Q4: Rev Reason | U4: IMHOGEN LTD
A5: Signature | E5: Docu. ID | G5: D1.7 | I5: Date Checked | Q5: Change Dscrpt. | U5: Copyright IMHO GEN 2026.
E6: Sheet Version | G6: v1.0 | I6: Date Approved | U6: All Rights Reserved
A7: PROJECT REQUEST ID: [Enter ID]
A8: D1.7 RAW MEETING NOTES (Live Capture)
A9: 1.0 MEETING EXECUTION METADATA
A10: Actual Date: | F10: Date (DD/MM/YYY) | K10: Actual Start Time:
A11: Recording Link (If applicable): | K11: Actual End Time:
A12: Attendees Present (IMHOGEN): | K12: Attendees Present (Client):
A15: 2.0 LIVE DISCUSSION CAPTURE (Aligns with D1.6 Agenda)
A16: SN | B16: Time Allotted | D16: Agenda Topic | K16: Raw Notes / Direct Client Statements | P16: IMHOGEN Clarifications / Immediate Remarks
A17: 1 | B17: 05 Mins | D17: Introductions & Project Overview
A18: 2 | B18: 15 Mins | D18: Technical Requirements (Inputs/Outputs)
A19: 3 | B19: 10 Mins | D19: Operational Environment & Constraints
A20: 4 | B20: 05 Mins | D20: Commercial Expectations (Timeline/Budget)
A21: 5 | B21: 05 Mins | D21: Next Steps & Q&A
A30: 3.0 PARKING LOT (Unresolved Questions or Out-of-Scope Requests)
A31: SN | B31: Item Description | T31: Action Required / Who to resolve?
A41: 4.0 MEETING CLOSE-OUT
A42: Primary Outcome: | D42: [e.g. Needs Assessment Complete / Follow-up Call Required]
A44: Client Next Step: | D44: [e.g. Send existing site photos and layout dimensions]
A46: IMHOGEN Next Step: | D46: [e.g. Synthesize into D1.8 and begin Feasibility Report]

Sheet D1.8 Needs Assessment Notes
A1: Prepared by | E1: Tool title | G1: Needs Assessment Note | I1: Date filled | M1: Quality Target | O1: 4 | Q1: Related Tool | S1: Doc Control
A2: Role | E2: Project Reg. ID | I2: Time Started | M2: Bus. Target | O2: Qlty Delivery | Q2: Prev. Sheet Ref | S2: D1.8
A3: Checked by | E3: Phase Name | G3: Onboarding | I3: Time cmpltd | M3: Bus. Const | O3: Cost and Risk | Q3: Next Sheet Ref | S3: D1.9 | U3: IMHO GEN
A4: Org/Dept. | C4: R&D and BI | E4: Activity Name | G4: Needs Assessment Note | I4: Duration | M4: Iteration Num. | O4: 0 | Q4: Rev Reason | U4: IMHOGEN LTD
A5: Signature | E5: Docu. ID | G5: D1.8 | I5: Date Checked | Q5: Change Dscrpt. | U5: Copyright IMHO GEN 2026.
E6: Sheet Version | G6: v1.0 | I6: Date Approved | U6: All Rights Reserved
A7: PROJECT REQUEST ID: [Enter ID]
A8: D1.8 NEEDS ASSESSMENT NOTES (Engineering Synthesis)
A9: 1.0 SYNTHESIS METADATA
A10: Synthesized By (Lead Engineer):
A11: Date of Synthesis:
A12: Reference Raw Notes ID
A13: Client/Project Name:
A15: 2.0 LIVE DISCUSSION CAPTURE (Aligns with D1.6 Agenda)
A16: SN | B16: Category | H16: Confirmed Constraints / Specifications | P16: Engineering Remarks (Risks/Clarifications)
A17: 1 | B17: INPUT: Material
A18: 2 | B18: INPUT: Energy
A19: 3 | B19: INPUT: Information
A20: 4 | B20: INPUT: Livingthing
A21: 5 | B21: OUTPUT: Material
A22: 6 | B22: OUTPUT: Energy
A23: 7 | B23: OUTPUT: Information
A24: 8 | B24: OUTPUT: Livingthing
A25: 9 | B25: OPERATOR: Human System
A26: 10 | B26: OPERATOR: Tech System
A27: 11 | B27: OPERATOR: Active Env.
A28: 12 | B28: OPERATOR: Mgt System
A29: 13 | B29: OPERATOR: Information System
A30: 3.0 PRELIMINARY DESIGN SPECIFICATIONS (Draft Pr-Set)
A31: SN | B31: Requirement Category | H31: Specific Requirement / Tolerance | Q31: Priority (Fixed/Wish) | T31: Specific Requirement / Tolerance
A32: 3.1 | B32: Function Properties
A33: 3.2 | B33: Operational Properties
A34: 3.3 | B34: Manufacturing Properties
A35: 3.4 | B35: Environmental Properties
A36: 3.5 | B36: Distribution Properties
A37: 3.6
A38: 3.7
A39: 3.8
A40: 3.9
A41: 4.0 SYNTHESIS APPROVAL & ROUTING
...

Sheet T3.D1.8a Physical Metrology & M
A1: Prepared by | E1: Tool title | G1: T3 Physical Metrology Log | I1: Date filled | M1: Quality Target | O1: 5 | Q1: Related Tool | S1: T3.D6.5.0a
A2: Role | E2: Project Reg. ID | I2: Time Started | M2: Bus. Target | O2: Data Integrity | Q2: Prev. Sheet Ref | S2: T3.D1.3a
A3: Org/Dept. | C3: Engineering | E3: Activity Name | G3: Physical Measurement | I3: Duration | M3: Iteration Num. | O3: 0 | Q3: Rev Reason | U3: IMHO GEN
A4: Signature | E4: Docu. ID | G4: T3.D1.8a | I4: Date Checked | Q4: Change Dscrpt. | S4: Tier 3 Field Tool | U4: IMHOGEN LTD
U5: Copyright IMHO GEN 2026.
U6: All Rights Reserved
A9: 1.0 MEASUREMENT EQUIPMENT VERIFICATION
A10: Tool Used | C10: Serial # / ID | H10: Calibration Status | M10: Accuracy Range | S10: Notes
C11: [e.g. Digital Caliper] | H11: [ID-101] | M11: [Valid] | S11: [+/- 0.02mm]
C12: [e.g. Laser Scanner] | H12: [ID-202] | M12: [Valid] | S12: [+/- 0.10mm]
A14: 2.0 CRITICAL DIMENSION CAPTURE
A15: SN | B15: Feature Name | F15: Measurement Method | J15: Measured Value (mm) | N15: Ref. Photo ID | R15: Confidence (H/M/L) | U15: Notes
A16: 2.1 | B16: Main Shaft Dia. | F16: [Caliper] | J16: [Value] | N16: [IMG_001] | R16: [High] | U16: [Measured at 3 points]
A17: 2.2 | B17: Mounting Pattern | F17: [Steel Rule] | J17: [Value] | N17: [IMG_002] | R17: [Med] | U17: [Center-to-center]
A18: 2.3 | B18: Overall Envelope | F18: [Laser Tape] | J18: [Value] | N18: [IMG_003] | R18: [High] | U18: [Max protrusion points]
A20: 3.0 PHOTOGRAPHIC EVIDENCE CHECKLIST
A21: SN | B21: View Required | F21: Captured? (Y/N) | J21: File Link / Folder | O21: Quality Note
A22: 3.1 | B22: Isometric / 3/4 View | F22: [ ] | J22: [Link] | O22: [Must show overall machine context]
A23: 3.2 | B23: Nameplate / Specs | F23: [ ] | J23: [Link] | O23: [Serial numbers and motor ratings]
A24: 3.3 | B24: Complex Interfaces | F24: [ ] | J24: [Link] | O24: [Close-ups of gears/splines/connectors]
A26: 4.0 FIELD SIGN-OFF
A27: I confirm that all critical dimensions have been captured and the physical machine can be released.
A28: Lead Measurer Signature | M28: Date | Q28: [DD/MM/YYYY]

Sheet D1.9 Internal Review Request
A1: Prepared by | E1: Tool title | G1: Internal Review Request | I1: Date filled | M1: Quality Target | O1: 4 | Q1: Related Tool | S1: Doc Control
A2: Role | E2: Project Reg. ID | I2: Time Started | M2: Bus. Target | O2: Qlty Delivery | Q2: Prev. Sheet Ref | S2: D1.8
A3: Checked by | E3: Phase Name | G3: Onboarding | I3: Time cmpltd | M3: Bus. Const | O3: Cost and Risk | Q3: Next Sheet Ref | S3: D1.10 | U3: IMHO GEN
A4: Org/Dept. | C4: R&D and BI | E4: Activity Name | G4: Internal Review Request | I4: Duration | M4: Iteration Num. | O4: 0 | Q4: Rev Reason | U4: IMHOGEN LTD
A5: Signature | E5: Docu. ID | G5: D1.9 | I5: Date Checked | Q5: Change Dscrpt. | U5: Copyright IMHO GEN 2026.
E6: Sheet Version | G6: v1.0 | I6: Date Approved | U6: All Rights Reserved
A7: PROJECT REQUEST ID: [Enter ID]
A8: D1.9 INTERNAL REVIEW REQUEST (Internal Memo)
A9: 1.0 REVIEW INITIATION METADATA
A10: Requested By (Lead/PM): | Q10: Project/Client Name:
A11: Date of Synthesis: | Q11: Required Completion Date:
A12: Primary Review Objective: | Q12: Priority Level:
A13: Project/Client Name:
A15: 2.0 CONTEXT & REFERENCE MATERIAL (Required Reading)
A16: SN | B16: Document Name | H16: Direct Link to Document | P16: Status
A17: 1 | B17: D1.3 Received Request Record
A18: 2 | B18: D1.8 Needs Assessment Notes
A19: 3 | B19: Client Supplementary Uploads (D1.1)
A30: 3.0 SPECIFIC REVIEW DIRECTIVES & ASSIGNMENTS
A31: SN | B31: Review Category | H31: Assigned Reviewer | M31: Specific Focus / Question for Reviewer | V31: Status
A32: 1 | B32: Technical Feasibility | H32: Engineering Risk Officer | M32: Evaluate the physical constraints outlined in D1.8.
A33: 2 | B33: Resource Availability | H33: Head of Operations | M33: Check workshop/personnel capacity for requested timeline.
A34: 3 | B34: Commercial & Scope Alignment | H34: Project Manager | M34: Verify client budget expectations align with stated deliverables.
A35: 4 | B35: Specialist Review (If required) | H35: [Name] | M35: [Type specific technical or supply chain question here]
A36: 5
A37: 6
A41: 4.0 REVIEW COMPLETION TRACKING
A42: Are all reviews submitted? (Yes/No): | Q42: Date
A44: Lead Engineer Signature:
A46: Ready for Capability Assessment (D1.10)?:

Sheet D1.10 Capability Assessment She
A1: Prepared by | E1: Tool title | G1: Capability Assessment Sheet | I1: Date filled | M1: Quality Target | O1: 4 | Q1: Related Tool | S1: Doc Control
A2: Role | E2: Project Reg. ID | I2: Time Started | M2: Bus. Target | O2: Qlty Delivery | Q2: Prev. Sheet Ref | S2: D1.9
A3: Checked by | E3: Phase Name | G3: Onboarding | I3: Time cmpltd | M3: Bus. Const | O3: Cost and Risk | Q3: Next Sheet Ref | S3: D1.10 | U3: IMHO GEN
A4: Org/Dept. | C4: R&D and BI | E4: Activity Name | G4: Capability Assessment | I4: Duration | M4: Iteration Num. | O4: 0 | Q4: Rev Reason | U4: IMHOGEN LTD
A5: Signature | E5: Docu. ID | G5: D1.10 | I5: Date Checked | Q5: Change Dscrpt. | U5: Copyright IMHO GEN 2026.
E6: Sheet Version | G6: v1.0 | I6: Date Approved | U6: All Rights Reserved
A7: PROJECT REQUEST ID: [Enter ID]
A8: D1.10 CAPABILITY ASSESSMENT SHEET
A9: 1.0 REVIEW INITIATION METADATA
A10: Assessor (Head of Ops/Lead Eng): | Q10: Project/Client Name:
A11: Date of Assessment:
A12: Primary Review Objective:
A13: Reference Request ID:
A15: 2.0 TECHNICAL CAPABILITY (Engineering & Manufacturing)
A16: SN | B16: Evaluation Criteria | L16: Status (Yes/No/Partial) | P16: Justification / Identified Gaps
A17: 2.1 | B17: Does IMHOGEN possess the core engineering expertise for this design?
A18: 2.2 | B18: Can the physical product be fabricated using our standard workshop tools?
A19: 2.3 | B19: Are the required raw materials reliably accessible in our local supply chain?
A20: 2.4 | B20: Do we have the software/computing capability to run necessary simulations?
A21: 2.1
A22: 2.2
A23: 2.3
A24: 2.4
A30: 4.0 COMMERCIAL ALIGNMENT
A31: SN | B31: Evaluation Criteria | L31: Status (Yes/No/Partial) | P31: Justification / Identified Gaps
A32: 2.1 | B32: Does the client's estimated budget align with the scale of work?
A33: 2.2 | B33: Is this project aligned with IMHOGEN's long-term strategic goals?
A34: 2.3
A35: 2.4
A36: 2.1
A37: 2.2
A38: 2.3
A39: 2.4
A44: 5.0 CAPABILITY CONCLUSION
A45: Overall Capability Status: | P45: Date:
A46: Primary Bottleneck (If any):
A47: Assessor Signature:

Sheet D1.11 RiskAssessment Sheet
A1: Prepared by | E1: Tool title | G1: Risk Assessment Sheet | I1: Date filled | M1: Quality Target | O1: 4 | Q1: Related Tool | S1: Doc Control
A2: Role | E2: Project Reg. ID | I2: Time Started | M2: Bus. Target | O2: Qlty Delivery | Q2: Prev. Sheet Ref | S2: D1.10
A3: Checked by | E3: Phase Name | G3: Onboarding | I3: Time cmpltd | M3: Bus. Const | O3: Cost and Risk | Q3: Next Sheet Ref | S3: D1.12 | U3: IMHO GEN
A4: Org/Dept. | C4: R&D and BI | E4: Activity Name | G4: Risk Assessment Sheet | I4: Duration | M4: Iteration Num. | O4: 0 | Q4: Rev Reason | U4: IMHOGEN LTD
A5: Signature | E5: Docu. ID | G5: D1.11 | I5: Date Checked | Q5: Change Dscrpt. | U5: Copyright IMHO GEN 2026.
E6: Sheet Version | G6: v1.0 | I6: Date Approved | U6: All Rights Reserved
A7: PROJECT REQUEST ID: [Enter ID]
A8: D1.11 RISK ASSESSMENT SHEET
A9: 1.0 ASSESSMENT METADATA
A10: Assessor (Head of Ops/Lead Eng): | Q10: Project/Client Name:
A11: Date of Assessment: | Q11: Overall Capability Status:
A12: Primary Review Objective:
A13: Reference Request ID:
A15: 2.0 TECHNICAL CAPABILITY (Engineering & Manufacturing)
A16: SN | B16: Risk Category | F16: Specific Risk Description | L16: Probability (H/M/L) | O16: Impact (H/M/L) | R16: Proposed Mitigation Strategy | W16: Risk Owner
A17: 2.1 | B17: Technical Risk | F17: [e.g. Thermal distortion during welding fails ±1mm tolerance]
A18: 2.2 | B18: Technical Risk | F18: [Type here]
A19: 2.2 | B19: Technical Risk | F19: [Type here]
A20: 2.3 | B20: Commercial Risk | F20: [e.g. Client expands scope without budget increase]
A21: 2.4 | B21: Commercial Risk | F21: [Type here]
A22: 2.5 | B22: Supply Chain Risk | F22: [e.g. Specific sensors unavailable in local Kumasi market]
A23: 2.6 | B23: Operational Risk | F23: [e.g. Workshop capacity full during target fabrication week]
A30: 3.0 RISK CONCLUSION & GO/NO-GO DECISION
A31: SN | B31: Evaluation Question | L31: Status (Yes/No/Partial) | P31: Remarks / Conditions
A32: 31 | B32: Are there any "High Probability / High Impact" risks that cannot be mitigated?
A33: 3.2 | B33: Does the mitigation of these risks push the project over the client's budget?
A34: 3.3 | B34: Is IMHOGEN willing to accept the residual risk of this project?
A35: 3.4
A36: 3.4
A37: 2.2
A38: 2.3
A39: 2.4
A44: 5.0 CAPABILITY CONCLUSION
A45: OVERALL RISK PROFILE: | P45: Date:
A46: PROJECT GO/NO-GO DECISION:
A47: Assessor Signature:

Sheet D1.12 Feasibility Report
A1: Prepared by | E1: Tool title | G1: Feasibility Report | I1: Date filled | M1: Quality Target | O1: 4 | Q1: Related Tool | S1: Doc Control
A2: Role | E2: Project Reg. ID | I2: Time Started | M2: Bus. Target | O2: Qlty Delivery | Q2: Prev. Sheet Ref | S2: D1.11
A3: Checked by | E3: Phase Name | G3: Onboarding | I3: Time cmpltd | M3: Bus. Const | O3: Cost and Risk | Q3: Next Sheet Ref | S3: D1.13 | U3: IMHO GEN
A4: Org/Dept. | C4: R&D and BI | E4: Activity Name | G4: Feasibility Report | I4: Duration | M4: Iteration Num. | O4: 0 | Q4: Rev Reason | U4: IMHOGEN LTD
A5: Signature | E5: Docu. ID | G5: D1.12 | I5: Date Checked | Q5: Change Dscrpt. | U5: Copyright IMHO GEN 2026.
E6: Sheet Version | G6: v1.0 | I6: Date Approved | U6: All Rights Reserved
A7: PROJECT REQUEST ID: [Enter ID]
A8: D1.10 CAPABILITY ASSESSMENT SHEET
A9: 1.0 REVIEW INITIATION METADATA
A10: Assessor (Head of Ops/Lead Eng): | Q10: Project/Client Name:
A11: Date of Assessment: | Q11: Overall Capability Status:
A12: Primary Review Objective:
A13: Reference Request ID:
A15: 2.0 TECHNICAL CAPABILITY (Engineering & Manufacturing)
A16: SN | B16: Capability Domain | O16: Status[Capable/Partial] | R16: Key Findings / Gaps to Bridge
A17: 2.1 | B17: Engineering & Design
A18: 2.2 | B18: Manufacturing & Tools
A19: 2.2 | B19: Supply Chain & Materials
A20: 2.3 | B20: Resource Bandwidth
A23: 3.0 CRITICAL RISKS & REQUIRED MITIGATIONS (Sourced from D1.11)
A24: SN | B24: Primary Risk Identified | O24: Impact Level | R24: Mandatory Mitigation Strategy (Must be in Contract)
A25: 3.1
A26: 3.2
A37: 4.0 COMMERCIAL FEASIBILITY (Timeline & Budget Alignment)
A38: Client's Target Timeline: | O38: IMHOGEN Realistic Timeline:
A39: Client's Estimated Budget: | O39: IMHOGEN Estimated Cost Floor:
A40: Commercial Alignment Notes:
A44: 5.0 FINAL RECOMMENDATION & ROUTING
A45: Recommendation:
A46: Head of R&D Signature:
A47: Date:

Sheet D1.13 Draft Scope of Work
A1: Prepared by | E1: Tool title | G1: Draft Scope of Work | I1: Date filled | M1: Quality Target | O1: 4 | Q1: Related Tool | S1: Doc Control
A2: Role | E2: Project Reg. ID | I2: Time Started | M2: Bus. Target | O2: Qlty Delivery | Q2: Prev. Sheet Ref | S2: D1.12
A3: Checked by | E3: Phase Name | G3: Onboarding | I3: Time cmpltd | M3: Bus. Const | O3: Cost and Risk | Q3: Next Sheet Ref | S3: D1.14 | U3: IMHO GEN
A4: Org/Dept. | C4: R&D and BI | E4: Activity Name | G4: Draft Scope of Work | I4: Duration | M4: Iteration Num. | O4: 0 | Q4: Rev Reason | U4: IMHOGEN LTD
A5: Signature | E5: Docu. ID | G5: D1.13 | I5: Date Checked | Q5: Change Dscrpt. | U5: Copyright IMHO GEN 2026.
E6: Sheet Version | G6: v1.0 | I6: Date Approved | U6: All Rights Reserved
A7: PROJECT REQUEST ID: [Enter ID]
A8: D1.13 DRAFT SCOPE OF WORK (SOW)
A9: 1.0 SOW METADATA & OVERVIEW
A10: Drafted By (Lead Engineer/PM): | Q10: Project/Client Name:
A11: Date of Assessment:
A12: Date of Draft:
A13: Reference Request ID:
A14: Project Vision / Primary Goal:
A15: 2.0 INCLUDED SCOPE (Specific Deliverables)
A16: SN | B16: Deliverable Category | H16: Detailed Description of Deliverable | O16: Format / Quantity | R16: Delivery Phase
A17: 2.1 | B17: Engineering Design | H17: [e.g. 3D CAD modeling of the welding jig structure] | O17: [e.g. .STEP / Native CAD] | R17: [Phase 1]
A18: 2.2 | B18: Manufacturing Documentation | H18: [e.g. 2D fabrication drawings with GD&T limits] | O18: [e.g. PDF (A3)] | R18: [Phase 1]
A19: 2.3 | B19: Physical Fabrication | H19: [e.g. Fabrication and assembly of one (1) physical jig unit] | O19: [e.g. Physical Unit] | R19: [Phase 2]
A20: 2.4 | B20: Technical Documentation | H20: [e.g. Operator Manual and Maintenance Guide] | O20: [e.g. PDF (A4)] | R20: [Phase 3]
A21: 2.5 | B21: Training & Handover | H21: [e.g. Half-day on-site operator training at client facility] | O21: [e.g. In-person] | R21: [Phase 3]
A23: 3.0 EXCLUDED SCOPE (Out of Scope / "Not Included")
A24: SN | B24: Exclusion Category | I24: Description of Excluded Work (To prevent scope creep) | R24: Reasoning (Optional)
A25: 3.1
A26: 3.2
A31: 4.0 PHASED TIMELINE & MILESTONES
A32: Phase | B32: Phase Name | I32: Key Activities / Milestones | R32: Estimated Duration | U32: Target Completion
A37: 5.0 CLIENT RESPONSIBILITIES & DEPENDENCIES
A38: SN | B38: Requirement | I38: Description | R38: Due Date | U38: Status
A44: 6.0 SOW ROUTING
A45: Scope Locked?: | R45: Date
A46: PM / Lead Engineer Signature:
A47: Ready for Cost Estimation (D1.14)?:

Sheet D1.14 Cost Estimation
A1: Prepared by | E1: Tool title | G1: Cost Estimation | I1: Date filled | M1: Quality Target | O1: 4 | Q1: Related Tool | S1: Finance tool
A2: Role | E2: Project Reg. ID | I2: Time Started | M2: Bus. Target | O2: Qlty Delivery | Q2: Prev. Sheet Ref | S2: D1.13
A3: Checked by | E3: Phase Name | G3: Onboarding | I3: Time cmpltd | M3: Bus. Const | O3: Cost and Risk | Q3: Next Sheet Ref | S3: D1.15 | U3: IMHO GEN
A4: Org/Dept. | C4: R&D and ED | E4: Activity Name | G4: Cost Estimation | I4: Duration | M4: Iteration Num. | O4: 0 | Q4: Rev Reason | U4: IMHOGEN LTD
A5: Signature | E5: Docu. ID | G5: D1.14 | I5: Date Checked | Q5: Change Dscrpt. | U5: Copyright IMHO GEN 2026.
E6: Sheet Version | G6: v1.0 | I6: Date Approved | U6: All Rights Reserved
A7: PROJECT REQUEST ID: [Enter ID]
A8: D1.14 COST ESTIMATION SHEET (Executive Summary)
A9: 1.0 BASE TECHNICAL LABOR COST (From Pricing Calculator)
A10: SN | B10: Engineering Module (e.g. Mechanical/Electronics) | M10: Estimated Days | Q10: Daily Rate (GHS) | U10: Total Labor Cost (GHS)
A11: 1.1 | B11: [Type here] | M11: [Type here] | Q11: [e.g. 937.50] | U11: [Type here]
A12: 1.2 | B12: [Type here] | M12: [Type here] | Q12: [e.g. 937.50] | U12: [Type here]
A13: 1.3 | B13: [Type here]
A14: 1.4
A15: 1.5
B16: BASE LABOR SUBTOTAL
A17: 2.0 DIRECT PROJECT COSTS (Prototypes & Materials)
A18: SN | B18: Item Description | M18: Quantity | Q18: Unit Cost (GHS) | U18: Total Cost (GHS)
A19: 2.1 | B19: [e.g. 3D Printing Housing] | M19: [Type here] | Q19: [Type here] | U19: [Type here]
A20: 2.2 | B20: [e.g. Electronics Fabrication / PCB] | M20: [Type here] | Q20: [Type here] | U20: [Type here]
A26: DIRECT COST SUBTOTAL:
A27: 3.0 INSTITUTIONAL MARKUP LAYERS (Protecting the Business)
A28: SN | B28: Cost Layer Category | M28: Applied Rate (%) | Q28: Calculated Value (GHS) | U28: Notes / Justification
A29: 3.1 | B29: Project Management & QC | M29: [e.g. 15%] | Q29: [Type here] | U29: [Applied to Base Labor]
A30: 3.2 | B30: Administrative Overhead | M30: [e.g. 7%] | Q30: [Type here] | U30: [Fixed Institutional Cost]
A31: 3.3 | B31: Sustainability / Risk Margin | M31: [e.g. 15%] | Q31: [Type here] | U31: [Varies by Project Risk (D1.11)]
A35: TOTAL PROJECT VALUE:
A36: 4.0 FINAL ALLOCATED BUDGET (Client-Facing Numbers)
A37: SN | B37: Deliverable Category (Must match SOW D1.13) | M37: Fully Loaded Alloc. Cost (GHS) | Q37: Allocation Check
A38: 4.1 | B38: [e.g. Product Architecture & System Design] | M38: [e.g. 24,238] | Q38: [Labor + Prop. PM + Overhead + Margin]
A39: 4.2 | B39: [e.g. Mechanical & Industrial Design] | M39: [e.g. 37,356]
A40: 4.3 | B40: [e.g. Prototype Fabrication & Testing] | M40: [e.g. 43,656]
A44: 5.0 FINANCIAL ROUTING & APPROVAL
A45: Is the minimum overhead recovery met? | O45: Ready for Project Briefing (D1.15)?:
A46: Lead Engineer Signature: | O46: Head of R&D / Finance Sig:

Sheet D1.15 Project Brief & Draft Bud
A1: Prepared by | C1: C.Fiannaa | E1: Tool title | G1: Project Brief & Draft Budget | I1: Date filled | K1: 46117 | M1: Quality Target | Q1: Related Tool | S1: Doc Control
A2: Role | C2: Ops. Lead | E2: Project Reg. ID | I2: Time Started | M2: Bus. Target | O2: Qlty Delivery | Q2: Prev. Sheet Ref | S2: D1.14
A3: Checked by | E3: Phase Name | G3: Onboarding | I3: Time cmpltd | M3: Bus. Const | O3: Cost and Risk | Q3: Next Sheet Ref | S3: D1.16 | U3: IMHO GEN
A4: Org/Dept. | C4: R&D and ED | E4: Activity Name | G4: Project Brief & Draft Budget | I4: Duration | M4: Iteration Num. | O4: 0 | Q4: Rev Reason | U4: IMHOGEN LTD
A5: Signature | E5: Docu. ID | G5: D1.3 | I5: Date Checked | Q5: Change Dscrpt. | U5: Copyright IMHO GEN 2026.
E6: Sheet Version | G6: v1.0 | I6: Date Approved | U6: All Rights Reserved
A7: PROJECT REQUEST ID: CAD-1775340276795
A8: D1.15 PROJECT BRIEF & DRAFT BUDGET
A9: 1.0 PROJECT & CLIENT OVERVIEW
A10: Client / Organization Name: | F10: Syntropy Engineering Solutions | Q10: Project Title: | U10: Prototype Digitization & Patent Documentation Package
A11: Primary Contact Person: | F11: Frederick Opoku | Q11: Estimated Project Duration: | U11: 5 Working Days
A12: Contact Email / Phone: | F12: 0267384812 | Q12: Target Start Date: | U12: To be confirmed upon client approval
A13: Reference Request ID: | F13: CAD-1775340276795
A15: 2.0 EXECUTIVE SUMMARY & CORE OBJECTIVES
A16: Project Vision: | F16: To transform an existing physical prototype into a precise digital engineering asset, supported by patent-compliant technical documentation, enabling successful Intellectual Property (IP) registration and future product development.
A19: Primary Objectives | F19: Digitize the prototype into an accurate 3D CAD model
F20: Develop detailed engineering drawings aligned with ISO standards
F21: Produce patent-compliant technical illustrations based on provided reference
F22: Deliver multi-format outputs suitable for documentation, submission, and presentation
F23: Ensure dimensional accuracy through on-site measurement and validation
A26: 3.0 PHASED DELIVERABLES & TIMELINE (Abstracted from D1.13 SOW)
A27: Phase No. | D27: Phase Name | J27: Key Deliverables Included | P27: Estimated Duration | U27: Target Completion
A28: 1 | D28: Measurement & Validation | J28: On-site prototype measurement and proportionality/dimensional data capture | P28: 1 Day | U28: Day 1
A29: 2 | D29: 3D Modeling (Parts + Assembly) | J29: Parametric 3D CAD model of prototype | P29: 2 Days | U29: Day 3
A30: 3 | D30: Technical Drafting | J30: 2D engineering drawings (ISO 128 compliant) | P30: 1 Day | U30: Day 4
A31: 4 | D31: Patent Drawing Set | J31: Patent-style line drawings (vector formats) | P31: 1 Day | U31: Day 5
A32: 5 | D32: Rendering and Packaging | J32: Rendered visuals and final file compilation | P32: 1 Day | U32: Day 5
A34: 4.0 PROJECT BUDGET SUMMARY (Value-Based Pricing - Sourced from D1.14 Sec 4.0)
A35: SN | D35: Project Deliverable / Component | P35: Allocated Value (GHS) | U35: Payment Schedule
A36: 1 | D36: Reverse Engineering & 3D Modeling | P36: =50%*'T3.D1.15a Drafting SOW '!N23 -> 3312 | U36: 50% at Project initiation
A37: 2 | D37: Technical Drawing Package (ISO Standard) | P37: =10%*'T3.D1.15a Drafting SOW '!N23 -> 662.4
A38: 3 | D38: Patent Drawing Development (Compliance Formatting) | P38: =15%*'T3.D1.15a Drafting SOW '!N23 -> 993.6 | U38: 25% at patent compliance formatting
A39: 4 | D39: Measurement, proportionation & Validation | P39: =5%*'T3.D1.15a Drafting SOW '!N23 -> 331.2
A40: 5 | D40: Rendering & Documentation Packaging | P40: =20%*'T3.D1.15a Drafting SOW '!N23 -> 1324.8 | U40: 25% Final delivery
A42: TOTAL ESTIMATED INVESTMENT (GHS): | U42: =sum(P36:T40) -> 6624
A43: 5.0 KEY EXCLUSIONS & CLIENT RESPONSIBILITIES
A44: Out of Scope (Not Included): | E44: Structural analysis or FEA Material selection or engineering optimization Patent filing services (only documentation support provided) Fabrication or manufacturing execution Product redesign or feature modification
A45: Client Dependencies: | E45: Access to physical prototype for measurement Clarification of any hidden/internal features if required Timely communication and approval during execution Confirmation of patent drawing standard if required
A47: 6.0 APPROVAL & NEXT STEPS
A48: Notice: | G48: This is a Draft Budget for discussion purposes. A formal binding contract will be issued upon agreement of these terms.
...

Sheet T3.D1.15a Drafting SOW 
A1: Prepared by | C1: C.Fiannaa | E1: Tool title | G1: T3 Drafting SOW & Quote | I1: Date filled | M1: Quality Target | O1: 4 | Q1: Related Tool | S1: T3.D2.2a
A2: Role | C2: Ops. Lead | E2: Project Reg. ID | G2: CAD-1775340276795 | I2: Time Started | M2: Bus. Target | O2: Conversion | Q2: Prev. Sheet Ref | S2: T3.D1.3a
A3: Org/Dept. | C3: R&D and ED | E3: Activity Name | G3: Drafting Quoting | I3: Duration | M3: Iteration Num. | O3: 0 | Q3: Rev Reason | U3: IMHO GEN
A4: Signature | E4: Docu. ID | G4: T3.D1.15a | I4: Date Checked | Q4: Change Dscrpt. | S4: Tier 3 Fast-Track | U4: IMHOGEN LTD
U5: Copyright IMHO GEN 2026.
U6: All Rights Reserved
A7: PROJECT REQUEST ID: CAD-1775340276795
A8: 1.0 SCOPE OF DELIVERABLES
A10: SN | B10: Service Item | G10: Technical Description | M10: Qty | P10: Delivery Timeline | V10: Format
A11: 1.1 | B11: 3D Modeling | G11: Reverse engineering and parametric reconstruction of prototype into a precise 3D CAD model | M11: 1 | P11: 3–4 Working Days | V11: STEP/Parasolid
A12: 1.2 | B12: Drafting Package | G12: Full 2D technical drawings (dimensions, orthographic views, sections) aligned with ISO 128 | M12: 1 | P12: 2–3 Working Days | V12: PDF/DWG
A13: 1.3 | B13: Patent Drawing Set | G13: Patent-compliant technical illustrations (black line format, no shading, standardized views) | M13: 1 | P13: 2–3 Working Days | V13: SVG / AI / EPS / PDF
A14: 1.4 | B14: Rendered Images | G14: High-quality visual renders for presentation and documentation support | M14: 3 Views | P14: 1–2 Working Days | V14: PNG / JPEG
A15: 1.5 | B15: Measurement & Validation | G15: On-site measurement and dimensional validation of prototype at client location (Suame) | M15: 1 Visit | P15: 1 Day | V15: Field Data + Notes
A17: 2.0 PRICING SUMMARY (GHS)
A18: SN | B18: Description | I18: Rate (Ghs/hr) | L18: Qty | N18: Subtotal | S18: Finance Notes
A19: 2.1 | B19: Engineering Man-Hours (Drafting & Modeling) | I19: 150 | L19: 32 | N19: =I19*L19 -> 4800 | S19: Covers 3D modeling, drawings, patent formatting
A20: 2.2 | B20: Reverse Engineering (Measurement & Validation Support) | I20: 0.05 | L20: 1 | N20: =I20*N19 -> 240 | S20: Includes short site visit + dimensional capture
A21: 2.3 | B21: Patent Drawing Preparation Premium | I21: 0.25 | L21: 1 | N21: =I21*N19 -> 1200 | S21: High-accuracy + compliance formatting
A22: 2.4 | B22: Markup / Admin Fee | I22: 0.08 | L22: 1 | N22: =I22*N19 -> 384 | S22: Coordination, QA, file packaging
A23: TOTAL T3 PROJECT VALUE | N23: =SUM(N19:N22) -> 6624
A25: 3.0 MANDATORY EXCLUSIONS
A26: SN | B26: Exclusion
A27: 1 | B27: No Structural Analysis or FEA included.
A28: 2 | B28: No Material Selection Advice.
A29: 3 | B29: No Fabrication Liability.
A30: 4 | B30: No Patent Filing Services (only drawing support)
A31: 5 | B31: No redesign or feature modification beyond existing prototype

Sheet D1.16 Hands Off Meeting
A1: Prepared by | E1: Tool title | G1: Initial Inquiry Notification | I1: Date filled | M1: Quality Target | O1: 4 | Q1: Related Tool | S1: Doc Control
A2: Role | E2: Project Reg. ID | I2: Time Started | M2: Bus. Target | O2: Qlty Delivery | Q2: Prev. Sheet Ref | S2: D1.5
A3: Checked by | E3: Phase Name | G3: Onboarding | I3: Time cmpltd | M3: Bus. Const | O3: Cost and Risk | Q3: Next Sheet Ref | S3: D1.7 | U3: IMHO GEN
A4: Org/Dept. | C4: R&D and ED | E4: Activity Name | G4: Inquiry Receipt | I4: Duration | M4: Iteration Num. | O4: 0 | Q4: Rev Reason | U4: IMHOGEN LTD
A5: Signature | E5: Docu. ID | G5: D1.16 | I5: Date Checked | Q5: Change Dscrpt. | U5: Copyright IMHO GEN 2026.
E6: Sheet Version | G6: v1.0 | I6: Date Approved | U6: All Rights Reserved
A7: PROJECT REQUEST ID: [Enter ID]
A8: D1.16 HANDOFF MEETING MINUTES (Engineering to Contracting)
A9: 1.0 HANDOFF METADATA
A10: Meeting Date: | F10: [DD/MM/YYYY] | Q10: Meeting Time: | U10: [00:00 AM/PM]
A11: Lead Engineer (Handing Off): | F11: [Type Name] | Q11: Contract Admin (Receiving): | U11: [Type Name]
A12: Project/Client Name: | F12: [Type Name] | Q12: Project Value (GHS): | U12: [From D1.15]
A13: Reference Request ID:
A16: 2.0 PROJECT BRIEF & BUDGET TRANSFER
A17: Reference Document: | E17: D1.15 Project Brief & Draft Budget | M17: Link to D1.15: | Q17: [Insert Hyperlink]
A18: Scope Summary: | E18: [Type a 2-sentence summary of what IMHOGEN has committed to delivering.]
A19: Payment Terms Agreed: | E19: [e.g. 40% Advance / 40% Fabrication / 20% Handover]
A21: 3.0 CONTRACTING DIRECTIVES (Critical Risks & Exclusions to enforce in Contract)
A22: SN | B22: Risk / Exclusion Category | H22: Specific Directive for Contract Admin | T22: Source Reference
A23: 3.1 | B23: Scope Exclusion | H23: [e.g. Ensure contract explicitly states regulatory certification is NOT included.] | T23: [From D1.13]
A24: 3.2 | B24: Timeline Risk | H24: [e.g. Add clause: Phase 2 timeline begins ONLY after formal CAD sign-off.] | T24: [From D1.11]
A25: 3.3 | B25: Financial Risk | H25: [e.g. Add clause: Quote valid for 21 days due to material price fluctuations.] | T25: [From D1.15]
A26: 3.4 | B26: [Type here] | H26: [Type here] | T26: [Type here]
A28: 4.0 SYSTEM HANDOFF & ARCHIVAL CHECKLIST (PID 1.5.2 & 1.5.3)
A29: Task / Action Item | M29: Assignee | T29: Status
A30: Has the central database status been updated to "Contracting Phase"? | M30: Contract Admin | T30: [Pending / Done]
A31: Have all D1.1 to D1.15 documents been moved to the permanent digital folder? | M31: Lead Engineer | T31: [Pending / Done]
A32: Is the Contract Admin fully clear on the technical deliverables to be billed? | M32: Contract Admin | T32: [Pending / Done]
A34: 5.0 FINAL SIGN-OFF
A35: Engineering Release: | E35: [Signature] | M35: Contracting Acceptance: | Q35: [Signature]
A36: Date: | E36: [DD/MM/YYYY] | M36: Date: | Q36: [DD/MM/YYYY]

Sheet Aux. Invoice
F1: INVOICE
A2: IMHO GEN
A3: Engineering Ideas Into Impact | E3: Invoice No: | F3: IMHO-INV26-ADV-012
A4: Designing solutions. Building skills. | E4: Invoice Type: | F4: ADV / MIL / FIN
A5: Powering industry. | E5: Invoice Date: | F5: 46118
E6: Due Date: | F6: 21 working days
A7: KBI, Near UPK, Opoku WareII Museum | E7: Project Code: | F7: CAD-1775340276795
A8: KNUST, Kumasi – Ghana admin@imhogen.com | E8: Project Title: | F8: Prototype Digitization & Patent Documentation Package
A11: BILLED BY: | E11: BILLED TO:
A12: IMHOGEN LTD | E12: Client Organisation: | F12: Syntropy Engineering Solutions
A13: Reg No: CS011410126 | E13: Client Address: | F13: Suame Magazine
A14: TIN: C006744075 | E14: Contact Person: | F14: Frederick Opoku
A15: Prepared by: | E15: Email: | F15: dir@syntropyengineeringsolutionss.com
A16: Clifford Fiannaa | E16: Phone: | F16: 0267384812
A17: Kumasi, Ghana
A19: ENGAGEMENT DESCRIPTION
A20: Provision of reverse engineering, 3D CAD modeling, technical drafting, and patent-compliant documentation services for the digitization and formal representation of an existing prototype
A22: Item | B22: Description | F22: Amount (GHS)
A23: 1 | B23: ='D1.15 Project Brief & Draft Bud'!D36 -> Reverse Engineering & 3D Modeling | F23: ='D1.15 Project Brief & Draft Bud'!P36 -> 3312
A24: 2 | B24: ='D1.15 Project Brief & Draft Bud'!D37 -> Technical Drawing Package (ISO Standard) | F24: ='D1.15 Project Brief & Draft Bud'!P37 -> 662.4
A25: 3 | B25: ='D1.15 Project Brief & Draft Bud'!D38 -> Patent Drawing Development (Compliance Formatting) | F25: ='D1.15 Project Brief & Draft Bud'!P38 -> 993.6
A26: 4 | B26: ='D1.15 Project Brief & Draft Bud'!D39 -> Measurement, proportionation & Validation | F26: ='D1.15 Project Brief & Draft Bud'!P39 -> 331.2
A27: 5 | B27: ='D1.15 Project Brief & Draft Bud'!D40 -> Rendering & Documentation Packaging | F27: ='D1.15 Project Brief & Draft Bud'!P40 -> 1324.8
A30: Subtotal | F30: =sum(F23:F29) -> 6624
A31: AMOUNT DUE | F31: =F30 -> 6624
A33: PAYMENT MILESTONE | E33: PAYMENT DETAILS
A34: Project Value: | C34: =F31 -> 6624 | E34: Bank: | F34: FIDELITY BANK
A35: Contract signing (50%): | C35: =F31*50% -> 3312 | E35: Account Name: | F35: IMHOGEN LTD
E36: Account Number: | F36: 1050432877614
A37: Please reference: | E37: Branch: | F37: KNUST
A38: Invoice No: | C38: =F3 -> IMHO-INV26-ADV-012
A40: PAYMENT TERMS
A41: This invoice is valid within 21 days from date of issue
A42: Work commencement is subject to receipt of the required advance payment.
A43: IMHO GEN reserves the right to suspend services or withhold deliverables until outstanding payments are settled.
A45: IMHOGEN LTD | Trading as IMHO GEN (A company incorporated under the laws of the Republic of Ghana)
A46: Engineering Design | Eng. Design Skills Development | R&D | QMS | Productivity Consulting | Innovation for Africa
